Loaded module: cuda/11.6
Loaded dependency [python3/3.11.4]: gcc/12.3.0-binutils-2.40
Loaded dependency [python3/3.11.4]: sqlite3/3.42.0
Loaded module: python3/3.11.4

Loading python3/3.11.4
  Loading requirement: gcc/12.3.0-binutils-2.40 sqlite3/3.42.0
Traceback (most recent call last):
  File "/appl/python/3.11.4/lib/python3.11/configparser.py", line 862, in items
    d.update(self._sections[section])
             ~~~~~~~~~~~~~~^^^^^^^^^
KeyError: 'Models'

During handling of the above exception, another exception occurred:

Traceback (most recent call last):
  File "/zhome/03/c/164482/code/herd/main.py", line 68, in <module>
    main()
  File "/zhome/03/c/164482/code/herd/main.py", line 36, in main
    model_values = ModelValues(**dict(config.items("Models")))
                                      ^^^^^^^^^^^^^^^^^^^^^^
  File "/appl/python/3.11.4/lib/python3.11/configparser.py", line 865, in items
    raise NoSectionError(section)
configparser.NoSectionError: No section: 'Models'
